version: "3.9"

networks:
  my_network:

services:
  db:
    image: postgres:15
    volumes:
      - postgres-data:/var/lib/postgresql/data
    environment:
      - POSTGRES_USER=postgres
      - POSTGRES_PASSWORD=2030
      - POSTGRES_DB=remote_sensor
    ports:
      - "5432:5432"
    healthcheck:
      test: [ "CMD-SHELL", "pg_isready -U postgres" ]
      interval: 5s
      timeout: 20s
      retries: 5
    networks:
      - my_network

  pgadmin:
      image: dpage/pgadmin4
      environment:
        - PGADMIN_DEFAULT_EMAIL=pgadmin4@pgamin.org
        - PGADMIN_DEFAULT_PASSWORD=admin
      ports:  
        - "5050:80"
      networks:
        - my_network

  redis:
      image: "redis:latest"
      networks:
        - my_network

  app:
    build: .
    command: daphne -b 0.0.0.0 -p 8001 config.asgi:application && python manage.py runserver 0.0.0.0:8000
    volumes:
      - .:/usr/src/app
    ports:
      - "8000:8000"
    env_file:
      - .env
    depends_on:
      db:
        condition: service_healthy
    networks:
      - my_network

volumes:
  postgres-data:


